Workbook

Sheet INSTRUCTIVO LLAMADAS
A1: Llamadas seguimiento pacientes Atención Domiciliaria: Buenos días/tardes, habla con el auditor XXXXX XXXXXX, me comunica por favor con el paciente XXXX XXXX o familiar. ¿con quién tengo el gusto? Xxxxxx ¿Qué parentesco tiene con el paciente? Xxxxxxx. El motivo de mi llamada es con el fin de confirmar que a el/la paciente Néstor Pérez, se le esté prestando correctamente y a tiempo los servicios asignados. Me confirma por favor ¿Quién ha asistido hasta el momento? Gracias, ¿de estos servicios ya prestados, tiene alguna duda o inconformidad? ¿tiene alguna sugerencia que desee registrar en la llamada? Agradezco su información y su tiempo

Sheet Formato Seguimiento PHD
A1: REGIONAL | B1: MUNICIPIO | C1: DIRECCION | D1: BARRIO | E1: FECHA dd/mm/aa | F1: IPS QUE ATIENDE AL PACIENTE | G1: NOMBRE DEL PACIENTE | H1: TIPO DE DOCUMENTO | I1: NUMERO DOCUMENTO | J1: TELEFONO 1 | K1: TELEFONO 2 | L1: CIE_10 | M1: DESCRIPCION CIE_10 | N1: COMPLEJIDAD | O1: TIPO DE INTERVENCION | P1: NUMERO DE VISITAS POR DIA | Q1: NOMBRE DE QUIEN ATIENDE LA LLAMADA | R1: PARENTESCO | S1: COMENTARIOS | T1: EFECTIVIDAD DE LA LLAMADA | U1: INTENTOS | AB1: TIPO
A2: CORDOBA | B2: MONTERIA | C2: B/ VILLA SORRENTO | D2: Mz7 L.10 | E2: 43221 | F2: MICASA MI HOSPITAL DE LA SABANA | G2: PAOLA HERNANDEZ VEGA | H2: CC | I2: 50919775 | J2: 3007763838 | L2: G822 | M2: =VLOOKUP(L2,[1]CIE10!$A:$C,3,0) -> PARAPLEJIA, NO ESPECIFICADA | N2: CRONICO | O2: ENFERMERA 12 H | P2: 1 | Q2: PAOLA HERNANDEZ | R2: PACIENTE
A3: CORDOBA | B3: MONTERIA | C3: B/ VILLA SORRENTO | D3: Mz7 L.10 | E3: 43221 | F3: MICASA MI HOSPITAL DE LA SABANA | G3: PAOLA HERNANDEZ VEGA | H3: CC | I3: 50919775 | J3: 3007763838 | L3: G822 | M3: =VLOOKUP(L3,[1]CIE10!$A:$C,3,0) -> PARAPLEJIA, NO ESPECIFICADA | N3: CRONICO | O3: TER. FISICA | P3: 1 | Q3: PAOLA HERNANDEZ | R3: PACIENTE
A4: CORDOBA | B4: BUENAVISTA | C4: VEREDA COSTA RICA | D4: casa finca | E4: 43221 | F4: MICASA MI HOSPITAL DE LA SABANA | G4: LINA MARCELA TAMARA ORTIZ | H4: C.C | I4: 1067097250 | J4: 3215039052 | L4: G800 | M4: =VLOOKUP(L4,[1]CIE10!$A:$C,3,0) -> PARALISIS CEREBRAL ESPASTICA | N4: CRONICO | O4: ENFERMERA 24 H | P4: 1 | Q4: CENITH ORTIZ OYOLA | R4: MADRE
A5: CORDOBA | B5: BUENAVISTA | C5: VEREDA COSTA RICA | D5: casa finca | E5: 43221 | F5: MICASA MI HOSPITAL DE LA SABANA | G5: LINA MARCELA TAMARA ORTIZ | H5: C.C | I5: 1067097250 | J5: 3215039052 | L5: G800 | M5: =VLOOKUP(L5,[1]CIE10!$A:$C,3,0) -> PARALISIS CEREBRAL ESPASTICA | N5: CRONICO | O5: TER. FISICA | P5: 1 | Q5: CENITH ORTIZ OYOLA | R5: MADRE
A6: CORDOBA | B6: BUENAVISTA | C6: VEREDA COSTA RICA | D6: casa finca | E6: 43221 | F6: MICASA MI HOSPITAL DE LA SABANA | G6: LINA MARCELA TAMARA ORTIZ | H6: C.C | I6: 1067097250 | J6: 3215039052 | L6: G800 | M6: =VLOOKUP(L6,[1]CIE10!$A:$C,3,0) -> PARALISIS CEREBRAL ESPASTICA | N6: CRONICO | O6: VISITA MED. GENERAL | P6: 1 | Q6: CENITH ORTIZ OYOLA | R6: MADRE
A7: CORDOBA | B7: MONTERIA | C7: VIVIENDA IPS | D7: calle 13#4-41 | E7: 43221 | F7: MICASA MI HOSPITAL DE LA SABANA | G7: CAMILA CHAMORRO ESTRADA | H7: TI | I7: 1151452288 | J7: 3136252893 | K7: 3117320678 | L7: G800 | M7: =VLOOKUP(L7,[1]CIE10!$A:$C,3,0) -> PARALISIS CEREBRAL ESPASTICA | N7: CRONICO | O7: VISITA MED. GENERAL | P7: 1 | Q7: YOLFARIS ESTRADA | R7: MADRE
A8: CORDOBA | B8: MONTERIA | C8: VIVIENDA IPS | D8: calle 13#4-41 | E8: 43221 | F8: MICASA MI HOSPITAL DE LA SABANA | G8: CAMILA CHAMORRO ESTRADA | H8: TI | I8: 1151452288 | J8: 3136252893 | K8: 3117320678 | L8: G800 | M8: =VLOOKUP(L8,[1]CIE10!$A:$C,3,0) -> PARALISIS CEREBRAL ESPASTICA | N8: CRONICO | O8: ENFERMERA 24 H | P8: 1 | Q8: YOLFARIS ESTRADA | R8: MADRE
A9: CORDOBA | B9: MONTERIA | C9: VIVIENDA IPS | D9: calle 13#4-41 | E9: 43221 | F9: MICASA MI HOSPITAL DE LA SABANA | G9: CAMILA CHAMORRO ESTRADA | H9: TI | I9: 1151452288 | J9: 3136252893 | K9: 3117320678 | L9: G800 | M9: =VLOOKUP(L9,[1]CIE10!$A:$C,3,0) -> PARALISIS CEREBRAL ESPASTICA | N9: CRONICO | O9: TER. FISICA | P9: 2 | Q9: YOLFARIS ESTRADA | R9: MADRE
A10: CORDOBA | B10: MONTERIA | C10: VIVIENDA IPS | D10: calle 13#4-41 | E10: 43221 | F10: MICASA MI HOSPITAL DE LA SABANA | G10: CAMILA CHAMORRO ESTRADA | H10: TI | I10: 1151452288 | J10: 3136252893 | K10: 3117320678 | L10: G800 | M10: =VLOOKUP(L10,[1]CIE10!$A:$C,3,0) -> PARALISIS CEREBRAL ESPASTICA | N10: CRONICO | O10: TER. LENGUAJE | P10: 1 | Q10: YOLFARIS ESTRADA | R10: MADRE
A11: CORDOBA | B11: MONTERIA | C11: VIVIENDA IPS | D11: calle 13#4-41 | E11: 43221 | F11: MICASA MI HOSPITAL DE LA SABANA | G11: CAMILA CHAMORRO ESTRADA | H11: TI | I11: 1151452288 | J11: 3136252893 | K11: 3117320678 | L11: G800 | M11: =VLOOKUP(L11,[1]CIE10!$A:$C,3,0) -> PARALISIS CEREBRAL ESPASTICA | N11: CRONICO | O11: TER. RESPIRATORIO | P11: 1 | Q11: YOLFARIS ESTRADA | R11: MADRE
A12: CORDOBA | B12: MONTERIA | C12: B/SANTA FE | D12: MZ 12 L.9 | E12: 43221 | F12: MICASA MI HOSPITAL DE LA SABANA | G12: YARA BARRIENTOS VALVERDE | H12: CC | I12: 50931108 | J12: 3123386830 | K12: 3106939251 | L12: G822 | M12: =VLOOKUP(L12,[1]CIE10!$A:$C,3,0) -> PARAPLEJIA, NO ESPECIFICADA | N12: CRONICO | O12: TER. FISICA | P12: 1 | Q12: DOLORES BARRIENTOS | R12: MADRE
A13: CORDOBA | B13: MONTERIA | C13: B/VILLA MELISA | D13: Mz.45 L.14 | E13: 43241 | F13: MICASA MI HOSPITAL DE LA SABANA | G13: LISBELLY VARGAS TOVAR | H13: CC | I13: 1067944075 | J13: 3173214269 | L13: G402 | M13: =VLOOKUP(L13,'CIE10'!$A:$C,3,0) -> EPILEPSIA Y SINDROMES EPILEPTICOS SINTOMATICOS RELACIONADOS CON LOCALIZACIONES (FOCALES) (PARCIALES) Y CON ATAQUES PARCIALES COMPLEJOS | N13: CRONICO | O13: VISITA MED. GENERAL | P13: 1 | Q13: ANA MILENA TOVAR | R13: MADRE
A14: CORDOBA | B14: MONTERIA | C14: B/SANTA ELENA 4 | D14: A29#40-74 | E14: 43210 | F14: MICASA MI HOSPITAL DE LA SABANA | G14: LUIS FERNANDO LOPEZ ARTEAGA | H14: CC | I14: 10967175 | J14: 3106432129 | L14: G822 | M14: =VLOOKUP(L14,'CIE10'!$A:$C,3,0) -> PARAPLEJIA, NO ESPECIFICADA | N14: CRONICO | O14: TER. FISICA | P14: 1 | Q14: LUIS FERNANDO LOPEZ | R14: PACIENTE
A15: CORDOBA | B15: MONTERIA | C15: B/SANTA ELENA 4 | D15: A29#40-74 | E15: 43210 | F15: MICASA MI HOSPITAL DE LA SABANA | G15: LUIS FERNANDO LOPEZ ARTEAGA | H15: CC | I15: 10967175 | J15: 3106432129 | L15: G822 | M15: =VLOOKUP(L15,'CIE10'!$A:$C,3,0) -> PARAPLEJIA, NO ESPECIFICADA | N15: CRONICO | O15: TER. FISICA | P15: 1 | Q15: LUIS FERNANDO LOPEZ | R15: PACIENTE
M16: =VLOOKUP(L16,'CIE10'!$A:$C,3,0) -> #N/A
M17: =VLOOKUP(L17,'CIE10'!$A:$C,3,0) -> #N/A
M18: =VLOOKUP(L18,'CIE10'!$A:$C,3,0) -> #N/A
M19: =VLOOKUP(L19,'CIE10'!$A:$C,3,0) -> #N/A
M20: =VLOOKUP(L20,'CIE10'!$A:$C,3,0) -> #N/A
M21: =VLOOKUP(L21,'CIE10'!$A:$C,3,0) -> #N/A
M22: =VLOOKUP(L22,'CIE10'!$A:$C,3,0) -> #N/A
M23: =VLOOKUP(L23,'CIE10'!$A:$C,3,0) -> #N/A
M24: =VLOOKUP(L24,'CIE10'!$A:$C,3,0) -> #N/A
M25: =VLOOKUP(L25,'CIE10'!$A:$C,3,0) -> #N/A
M26: =VLOOKUP(L26,'CIE10'!$A:$C,3,0) -> #N/A
M27: =VLOOKUP(L27,'CIE10'!$A:$C,3,0) -> #N/A
... M635: =VLOOKUP(L635,'CIE10'!$A:$C,3,0) -> #N/A

Sheet Formato Visita PHD
A1: SEGUIMIENTO ATENCION DOMICILIARIA
A2: NOMBRE Y APELLIDOS DEL PACIENTE | C2: TIPO DE DOCUMENTO | D2: NUMERO DE DOCUMENTO
A4: EDAD: | C4: SEXO:
A5: DIRECCION DOMICILIO | C5: TELEFONOS
A6: DEPARTAMENTO | C6: MUNICIPIO
A7: FECHA DE LA VISITA | C7: HORA DE LA VISITA
A8: IPS PACIENTE
A9: NOMBRE DE QUIEN RECIBE LA VISITA
A10: PARENTESCO
A11: DIAGNOSTICO
A14: TRATAMIENTO INSTAURADO
A18: HALLAZGOS
A30: OBSERVACIONES, COMENTARIOS Y SUGERENCIAS DE AUDITORIA
A37: OBSERVACIONES, COMENTARIOS Y SUGERENCIAS DEL CUIDADOR
A39: NOMBRE AUDITOR

Sheet CIE10
A1: Código | B1: Simbolo | C1: Descripcion | D1: Sexo | E1: Límite inferior | F1: Límite superior | G1: No son afección principal | H1: Observaciones
A2: A000 | C2: COLERA DEBIDO A VIBRIO CHOLERAE O1, BIOTIPO CHOLERAE | D2: AMBOS | E2: 0 | F2: 0
A3: A001 | C3: COLERA DEBIDO A VIBRIO CHOLERAE O1, BIOTIPO EL TOR | D3: AMBOS | E3: 0 | F3: 0
A4: A009 | C4: COLERA NO ESPECIFICADO | D4: AMBOS | E4: 0 | F4: 0
A5: A010 | C5: FIEBRE TIFOIDEA | D5: AMBOS | E5: 0 | F5: 0
A6: A011 | C6: FIEBRE PARATIFOIDEA A | D6: AMBOS | E6: 0 | F6: 0
A7: A012 | C7: FIEBRE PARATIFOIDEA B | D7: AMBOS | E7: 0 | F7: 0
A8: A013 | C8: FIEBRE PARATIFOIDEA C | D8: AMBOS | E8: 0 | F8: 0
A9: A014 | C9: FIEBRE PARATIFOIDEA, NO ESPECIFICADA | D9: AMBOS | E9: 0 | F9: 0
A10: A020 | C10: ENTERITIS DEBIDA A SALMONELLA | D10: AMBOS | E10: 0 | F10: 0
A11: A021 | C11: SEPTICEMIA DEBIDA A SALMONELLA | D11: AMBOS | E11: 0 | F11: 0
A12: A022 | B12: † | C12: INFECCIONES LOCALIZADAS DEBIDA A SALMONELLA | D12: AMBOS | E12: 0 | F12: 0
A13: A028 | C13: OTRAS INFECCIONES ESPECIFICADAS COMO DEBIDAS A SALMONELLA | D13: AMBOS | E13: 0 | F13: 0
A14: A029 | C14: INFECCION DEBIDA A SALMONELLA NO ESPECIFICADA | D14: AMBOS | E14: 0 | F14: 0
A15: A030 | C15: SHIGELOSIS DEBIDA A SHIGELLA DYSENTERIAE | D15: AMBOS | E15: 0 | F15: 0
A16: A031 | C16: SHIGELOSIS DEBIDA A SHIGELLA FLEXNERI | D16: AMBOS | E16: 0 | F16: 0
A17: A032 | C17: SHIGELOSIS DEBIDA A SHIGELLA BOYDII | D17: AMBOS | E17: 0 | F17: 0
A18: A033 | C18: SHIGELOSIS DEBIDA A SHIGELLA SONNEI | D18: AMBOS | E18: 0 | F18: 0
A19: A038 | C19: OTRAS SHIGELOSIS | D19: AMBOS | E19: 0 | F19: 0
A20: A039 | C20: SHIGELOSIS DE TIPO NO ESPECIFICADO | D20: AMBOS | E20: 0 | F20: 0
A21: A040 | C21: INFECCION DEBIDA A ESCHERICHIA COLI ENTEROPATOGENA | D21: AMBOS | E21: 0 | F21: 0
A22: A041 | C22: INFECCION DEBIDA A ESCHERICHIA COLI ENTEROTOXIGENA | D22: AMBOS | E22: 0 | F22: 0
A23: A042 | C23: INFECCION DEBIDA A ESCHERICHIA COLI ENTEROINVASIVA | D23: AMBOS | E23: 0 | F23: 0
A24: A043 | C24: INFECCION DEBIDA A ESCHERICHIA COLI ENTEROHEMORRAGICA | D24: AMBOS | E24: 0 | F24: 0
... A42: A064 | C42: ABSCESO AMEBIANO DEL HIGADO | D42: AMBOS | E42: 0 | F42: 0
A43: A065 | B43: † | C43: ABSCESO AMEBIANO DEL PULMON (J99.8*) | D43: AMBOS | E43: 0 | F43: 0
A44: A066 | B44: † | C44: ABSCESO AMEBIANO DEL CEREBRO (G07*) | D44: AMBOS | E44: 0 | F44: 0
A45: A067 | C45: AMEBIASIS CUTANEA | D45: AMBOS | E45: 0 | F45: 0
A46: A068 | C46: INFECCION AMEBIANA DE OTRAS LOCALIZACIONES | D46: AMBOS | E46: 0 | F46: 0
A47: A069 | C47: AMEBIASIS, NO ESPECIFICADA | D47: AMBOS | E47: 0 | F47: 0
A48: A070 | C48: BALANTIDIASIS | D48: AMBOS | E48: 0 | F48: 0
A49: A071 | C49: GIARDIASIS [LAMBLIASIS] | D49: AMBOS | E49: 0 | F49: 0
A50: A072 | C50: CRIPTOSPORIDIOSIS | D50: AMBOS | E50: 0 | F50: 0
A51: A073 | C51: ISOSPORIASIS | D51: AMBOS | E51: 0 | F51: 0
A52: A078 | C52: OTRAS ENFERMEDADES INTESTINALES ESPECIFICADAS DEBIDAS A PROTOZOARIOS | D52: AMBOS | E52: 0 | F52: 0
A53: A079 | C53: ENFERMEDAD INTESTINAL DEBIDA A PROTOZOARIOS, NO ESPECIFICADA | D53: AMBOS | E53: 0 | F53: 0
A54: A080 | C54: ENTERITIS DEBIDA A ROTAVIRUS | D54: AMBOS | E54: 0 | F54: 0
A55: A081 | C55: GASTROENTEROPATIA AGUDA DEBIDA AL AGENTE DE NORWALK | D55: AMBOS | E55: 0 | F55: 0
A56: A082 | C56: ENTERITIS DEBIDA A ADENOVIRUS | D56: AMBOS | E56: 0 | F56: 0
... A60: A09X | C60: DIARREA Y GASTROENTERITIS DE PRESUNTO ORIGEN INFECCIOSO | D60: AMBOS | E60: 0 | F60: 0
...
